<?xml version="1.0" ?>
<!-- =================================================================================== -->
<!-- |    This document was autogenerated by xacro from scara.urdf.xacro               | -->
<!-- |    EDITING THIS FILE BY HAND IS NOT RECOMMENDED                                 | -->
<!-- =================================================================================== -->
<robot name="scara_robot">
  <material name="blue">
    <color rgba="0.0 0.0 1.0 1.0"/>
  </material>
  <material name="black">
    <color rgba="0.0 0.0 0.0 1.0"/>
  </material>
  <material name="white">
    <color rgba="1.0 1.0 1.0 1.0"/>
  </material>
  <material name="grey">
    <color rgba="0.5 0.5 0.5 1.0"/>
  </material>
  <link name="world"/>
  <link name="base_link">
    <visual>
      <origin rpy="0.0 0.0 0.0" xyz="0.0 0.0 0.5"/>
      <geometry>
        <cylinder length="1" radius="0.1"/>
      </geometry>
      <material name="black"/>
    </visual>
  </link>
  <joint name="base_joint" type="fixed">
    <parent link="world"/>
    <child link="base_link"/>
  </joint>
  <link name="arm1_cylinder">
    <visual>
      <origin rpy="0.0 0.0 0.0" xyz="0.0 0.0 0.0"/>
      <geometry>
        <cylinder length="0.2" radius="0.1"/>
      </geometry>
      <material name="white"/>
    </visual>
  </link>
  <joint name="arm1_joint_Gelenk" type="revolute">
    <origin rpy="0.0 0.0 0.0" xyz="0.0 0.0 1.1"/>
    <parent link="base_link"/>
    <child link="arm1_cylinder"/>
    <axis xyz="0.0 0.0 1.2"/>
    <limit effort="1000.0" lower="-1.0" upper="1.0" velocity="1000.0"/>
  </joint>
  <link name="arm1_connection">
    <visual>
      <origin rpy="0.0 1.57075 0.0" xyz="0.0 0.0 0.0"/>
      <geometry>
        <cylinder length="0.6" radius="0.05"/>
      </geometry>
      <material name="black"/>
    </visual>
  </link>
  <joint name="arm1_joint_box" type="fixed">
    <origin rpy="0.0 0.0 0.0" xyz="0.3 0.0 0.0"/>
    <parent link="arm1_cylinder"/>
    <child link="arm1_connection"/>
  </joint>
  <link name="arm2_cylinder1">
    <visual>
      <origin rpy="0.0 0.0 0.0" xyz="0.0 0.0 0.0"/>
      <geometry>
        <cylinder length="0.2" radius="0.1"/>
      </geometry>
      <material name="grey"/>
    </visual>
  </link>
  <joint name="arm2_joint_Gelenk" type="fixed">
    <origin rpy="0.0 0.0 0.0" xyz="0.3 0.0 0.0"/>
    <parent link="arm1_connection"/>
    <child link="arm2_cylinder1"/>
  </joint>
  <link name="arm2_cylinder2">
    <visual>
      <origin rpy="0.0 0.0 0.0" xyz="0.0 0.0 0.0"/>
      <geometry>
        <cylinder length="0.2" radius="0.1"/>
      </geometry>
      <material name="white"/>
    </visual>
  </link>
  <joint name="arm2_joint" type="revolute">
    <origin rpy="0.0 0.0 0.0" xyz="0.0 0.0 0.2"/>
    <parent link="arm2_cylinder1"/>
    <child link="arm2_cylinder2"/>
    <axis xyz="0.0 0.0 1.0"/>
    <limit effort="1000.0" lower="-1.0" upper="1.0" velocity="1000.0"/>
  </joint>
  <link name="arm2_connection">
    <visual>
      <origin rpy="0.0 1.57075 0.0" xyz="0.0 0.0 0.0"/>
      <geometry>
        <cylinder length="0.8" radius="0.05"/>
      </geometry>
      <material name="black"/>
    </visual>
  </link>
  <joint name="arm2_joint_box" type="fixed">
    <origin rpy="0.0 0.0 0.0" xyz="0.4 0.0 0.0"/>
    <parent link="arm2_cylinder2"/>
    <child link="arm2_connection"/>
  </joint>
  <link name="arm3_cylinder1">
    <visual>
      <origin rpy="0.0 0.0 0.0" xyz="0.0 0.0 0.0"/>
      <geometry>
        <cylinder length="0.2" radius="0.1"/>
      </geometry>
      <material name="grey"/>
    </visual>
  </link>
  <joint name="arm3_joint_Gelenk" type="fixed">
    <origin rpy="0.0 0.0 0.0" xyz="0.4 0.0 0.0"/>
    <parent link="arm2_connection"/>
    <child link="arm3_cylinder1"/>
  </joint>
  <link name="arm3_prismatic">
    <visual>
      <origin rpy="0.0 0.0 0.0" xyz="0.0 0.0 -0.2499999999999999"/>
      <geometry>
        <cylinder length="0.4999999999999998" radius="0.075"/>
      </geometry>
      <material name="white"/>
    </visual>
  </link>
  <joint name="arm3_joint" type="prismatic">
    <origin rpy="0.0 0.0 0.0" xyz="0.0 0.0 0.1"/>
    <parent link="arm3_cylinder1"/>
    <child link="arm3_prismatic"/>
    <axis xyz="0.0 0.0 1.0"/>
    <limit effort="1000.0" lower="0.0" upper="0.29999999999999977" velocity="1000.0"/>
  </joint>
  <link name="arm3_connection">
    <visual>
      <origin rpy="0.0 0.0 0.0" xyz="0.0 0.0 0.0"/>
      <geometry>
        <cylinder length="0.1" radius="0.025"/>
      </geometry>
      <material name="grey"/>
    </visual>
  </link>
  <joint name="arm3_joint_box" type="revolute">
    <origin rpy="0.0 0.0 0.0" xyz="0.0 0.0 -0.5499999999999998"/>
    <parent link="arm3_prismatic"/>
    <child link="arm3_connection"/>
    <axis xyz="0.0 0.0 1.0"/>
    <limit effort="1000.0" lower="-1.5" upper="1.5" velocity="1000.0"/>
  </joint>
  <link name="Hand_Base">
    <visual>
      <origin rpy="0.0 0.0 0.0" xyz="0.0 0.0 0.05"/>
      <geometry>
        <box size="0.1 0.1 0.1"/>
      </geometry>
      <material name="blue"/>
    </visual>
  </link>
  <joint name="Hand_Base_joint" type="fixed">
    <origin rpy="0.0 0.0 0.0" xyz="0.0 0.0 -0.15000000000000002"/>
    <parent link="arm3_connection"/>
    <child link="Hand_Base"/>
  </joint>
</robot>

